Workbook

Sheet Workout
B2: 이동주회원님
B4: 날짜 | D4: 유산소🔥 | H4: 수업⚡ | I4: 운동부위✔️ | J4: 웨이트 운동기록🏋️‍♀️ | AA4: 1회 최대반복 추정🤖 (kg)
B5: 46034 | C5: =if(B5="0/0","",choose(weekday(B5),"(일)","(월)","(화)","(수)","(목)","(금)","(토)")) -> (월) | D5: 걸음수 | E5: 러닝머신 | G5: 사이클 | H5: 수업 | I5: 등 | J5: 1set | L5: 2set | N5: 3set | P5: 4set | R5: 5set | T5: 6set | V5: 7set | X5: 8set | Z5: lb (파운드) | AA5: 무게 합 | AB5: 1RM 추정값 | AE5: MAX
B6: =iferror(B5-'현황'!$C$4+1,0) -> 0 | D6: 0 | E6: 0 | G6: 0 | H6: 0
B7: 오늘의 진단✅ | E7: 오늘의 식단🍚 | H7: 웨이트💪 | J7: 무게 | K7: 횟수 | L7: 무게 | M7: 횟수 | N7: 무게 | O7: 횟수 | P7: 무게 | Q7: 횟수 | R7: 무게 | S7: 횟수 | T7: 무게 | U7: 횟수 | V7: 무게 | W7: 횟수 | X7: 무게 | Y7: 횟수 | AB7: 1RM | AC7: 5RM | AD7: 12RM | AE7: 무게 | AF7: 횟수
B8: 숙면🌙 | E8: 아 침 | F8: 탄수화물 | H8: 렛풀다운 | J8: 10 | K8: 12 | L8: 10 | M8: 10 | N8: 10 | O8: 12 | P8: 10 | Q8: 15 | R8: 10 | S8: 15 | Z8: FALSE | AA8: =(J8*K8+L8*M8+N8*O8+P8*Q8+R8*S8+T8*U8+V8*W8+X8*Y8)*if(Z8=true,0.453592,1) -> 640 | AB8: =SUM(AE8*AF8*0.025,AE8) -> 13.75 | AC8: =AB8*87% -> 11.9625 | AD8: =AB8*67% -> 9.2125 | AE8: =MAX(J8,L8,N8,P8,R8,T8,V8,X8)*if(Z8=true,0.453592,1) -> 10 | AF8: =MAX(IF(J8*if(Z8=true,0.453592,1)=$AE8,K8,0),IF(L8*if(Z8=true,0.453592,1)=$AE8,M8,0),IF(N8*if(Z8=true,0.453592,1)=$AE8,O8,0),IF(P8*if(Z8=true,0.453592,1)=$AE8,Q8,0),IF(R8*if(Z8=true,0.453592,1)=$AE8,S8,0),IF(T8*if(Z8=true,0.453592,1)=$AE8,U8,0),IF(V8*if(Z8=true,0.453592,1)=$AE8,W8,0),IF(X8*if(Z8=true,0.453592,1)=$AE8,Y8,0)) -> 15
B9: 컨디션😀 | F9: 단백질 | H9: 시티드로우 | J9: 10 | K9: 5 | L9: 10 | M9: 5 | N9: 10 | O9: 5 | Z9: FALSE | AA9: =(J9*K9+L9*M9+N9*O9+P9*Q9+R9*S9+T9*U9+V9*W9+X9*Y9)*if(Z9=true,0.453592,1) -> 150 | AB9: =SUM(AE9*AF9*0.025,AE9) -> 11.25 | AC9: =AB9*87% -> 9.7875 | AD9: =AB9*67% -> 7.5375 | AE9: =MAX(J9,L9,N9,P9,R9,T9,V9,X9)*if(Z9=true,0.453592,1) -> 10 | AF9: =MAX(IF(J9*if(Z9=true,0.453592,1)=$AE9,K9,0),IF(L9*if(Z9=true,0.453592,1)=$AE9,M9,0),IF(N9*if(Z9=true,0.453592,1)=$AE9,O9,0),IF(P9*if(Z9=true,0.453592,1)=$AE9,Q9,0),IF(R9*if(Z9=true,0.453592,1)=$AE9,S9,0),IF(T9*if(Z9=true,0.453592,1)=$AE9,U9,0),IF(V9*if(Z9=true,0.453592,1)=$AE9,W9,0),IF(X9*if(Z9=true,0.453592,1)=$AE9,Y9,0)) -> 5
B10: 활동강도🔥 | F10: 지방 | Z10: FALSE | AA10: =(J10*K10+L10*M10+N10*O10+P10*Q10+R10*S10+T10*U10+V10*W10+X10*Y10)*if(Z10=true,0.453592,1) -> 0 | AB10: =SUM(AE10*AF10*0.025,AE10) -> 0 | AC10: =AB10*87% -> 0 | AD10: =AB10*67% -> 0 | AE10: =MAX(J10,L10,N10,P10,R10,T10,V10,X10)*if(Z10=true,0.453592,1) -> 0 | AF10: =MAX(IF(J10*if(Z10=true,0.453592,1)=$AE10,K10,0),IF(L10*if(Z10=true,0.453592,1)=$AE10,M10,0),IF(N10*if(Z10=true,0.453592,1)=$AE10,O10,0),IF(P10*if(Z10=true,0.453592,1)=$AE10,Q10,0),IF(R10*if(Z10=true,0.453592,1)=$AE10,S10,0),IF(T10*if(Z10=true,0.453592,1)=$AE10,U10,0),IF(V10*if(Z10=true,0.453592,1)=$AE10,W10,0),IF(X10*if(Z10=true,0.453592,1)=$AE10,Y10,0)) -> 0
B11: 식이조절😇 | D11: FALSE | E11: 점 심 | F11: 탄수화물 | Z11: FALSE | AA11: =(J11*K11+L11*M11+N11*O11+P11*Q11+R11*S11+T11*U11+V11*W11+X11*Y11)*if(Z11=true,0.453592,1) -> 0 | AB11: =SUM(AE11*AF11*0.025,AE11) -> 0 | AC11: =AB11*87% -> 0 | AD11: =AB11*67% -> 0 | AE11: =MAX(J11,L11,N11,P11,R11,T11,V11,X11)*if(Z11=true,0.453592,1) -> 0 | AF11: =MAX(IF(J11*if(Z11=true,0.453592,1)=$AE11,K11,0),IF(L11*if(Z11=true,0.453592,1)=$AE11,M11,0),IF(N11*if(Z11=true,0.453592,1)=$AE11,O11,0),IF(P11*if(Z11=true,0.453592,1)=$AE11,Q11,0),IF(R11*if(Z11=true,0.453592,1)=$AE11,S11,0),IF(T11*if(Z11=true,0.453592,1)=$AE11,U11,0),IF(V11*if(Z11=true,0.453592,1)=$AE11,W11,0),IF(X11*if(Z11=true,0.453592,1)=$AE11,Y11,0)) -> 0
B12: 수분🥛 | D12: FALSE | F12: 단백질 | Z12: FALSE | AA12: =(J12*K12+L12*M12+N12*O12+P12*Q12+R12*S12+T12*U12+V12*W12+X12*Y12)*if(Z12=true,0.453592,1) -> 0 | AB12: =SUM(AE12*AF12*0.025,AE12) -> 0 | AC12: =AB12*87% -> 0 | AD12: =AB12*67% -> 0 | AE12: =MAX(J12,L12,N12,P12,R12,T12,V12,X12)*if(Z12=true,0.453592,1) -> 0 | AF12: =MAX(IF(J12*if(Z12=true,0.453592,1)=$AE12,K12,0),IF(L12*if(Z12=true,0.453592,1)=$AE12,M12,0),IF(N12*if(Z12=true,0.453592,1)=$AE12,O12,0),IF(P12*if(Z12=true,0.453592,1)=$AE12,Q12,0),IF(R12*if(Z12=true,0.453592,1)=$AE12,S12,0),IF(T12*if(Z12=true,0.453592,1)=$AE12,U12,0),IF(V12*if(Z12=true,0.453592,1)=$AE12,W12,0),IF(X12*if(Z12=true,0.453592,1)=$AE12,Y12,0)) -> 0
B13: {="📌최근 인바디 결과 : "&text(xlookup(B5,'현황'!O:O,'현황'!O:O,,-1,-1),"m/d(ddd)")} -> #REF! | F13: 지방 | Z13: FALSE | AA13: =(J13*K13+L13*M13+N13*O13+P13*Q13+R13*S13+T13*U13+V13*W13+X13*Y13)*if(Z13=true,0.453592,1) -> 0 | AB13: =SUM(AE13*AF13*0.025,AE13) -> 0 | AC13: =AB13*87% -> 0 | AD13: =AB13*67% -> 0 | AE13: =MAX(J13,L13,N13,P13,R13,T13,V13,X13)*if(Z13=true,0.453592,1) -> 0 | AF13: =MAX(IF(J13*if(Z13=true,0.453592,1)=$AE13,K13,0),IF(L13*if(Z13=true,0.453592,1)=$AE13,M13,0),IF(N13*if(Z13=true,0.453592,1)=$AE13,O13,0),IF(P13*if(Z13=true,0.453592,1)=$AE13,Q13,0),IF(R13*if(Z13=true,0.453592,1)=$AE13,S13,0),IF(T13*if(Z13=true,0.453592,1)=$AE13,U13,0),IF(V13*if(Z13=true,0.453592,1)=$AE13,W13,0),IF(X13*if(Z13=true,0.453592,1)=$AE13,Y13,0)) -> 0
B14: 몸무게🙈 | D14: {=iferror(vlookup(xlookup(B5,'현황'!O:O,'현황'!O:O,,-1,-1),'현황'!O:S,2,false),0)} -> 0 | E14: 저 녁 | F14: 탄수화물 | Z14: FALSE | AA14: =(J14*K14+L14*M14+N14*O14+P14*Q14+R14*S14+T14*U14+V14*W14+X14*Y14)*if(Z14=true,0.453592,1) -> 0 | AB14: =SUM(AE14*AF14*0.025,AE14) -> 0 | AC14: =AB14*87% -> 0 | AD14: =AB14*67% -> 0 | AE14: =MAX(J14,L14,N14,P14,R14,T14,V14,X14)*if(Z14=true,0.453592,1) -> 0 | AF14: =MAX(IF(J14*if(Z14=true,0.453592,1)=$AE14,K14,0),IF(L14*if(Z14=true,0.453592,1)=$AE14,M14,0),IF(N14*if(Z14=true,0.453592,1)=$AE14,O14,0),IF(P14*if(Z14=true,0.453592,1)=$AE14,Q14,0),IF(R14*if(Z14=true,0.453592,1)=$AE14,S14,0),IF(T14*if(Z14=true,0.453592,1)=$AE14,U14,0),IF(V14*if(Z14=true,0.453592,1)=$AE14,W14,0),IF(X14*if(Z14=true,0.453592,1)=$AE14,Y14,0)) -> 0
B15: 골격근 | D15: {=iferror(vlookup(xlookup(B5,'현황'!O:O,'현황'!O:O,,-1,-1),'현황'!O:S,3,false),0)} -> 0 | F15: 단백질 | Z15: FALSE | AA15: =(J15*K15+L15*M15+N15*O15+P15*Q15+R15*S15+T15*U15+V15*W15+X15*Y15)*if(Z15=true,0.453592,1) -> 0 | AB15: =SUM(AE15*AF15*0.025,AE15) -> 0 | AC15: =AB15*87% -> 0 | AD15: =AB15*67% -> 0 | AE15: =MAX(J15,L15,N15,P15,R15,T15,V15,X15)*if(Z15=true,0.453592,1) -> 0 | AF15: =MAX(IF(J15*if(Z15=true,0.453592,1)=$AE15,K15,0),IF(L15*if(Z15=true,0.453592,1)=$AE15,M15,0),IF(N15*if(Z15=true,0.453592,1)=$AE15,O15,0),IF(P15*if(Z15=true,0.453592,1)=$AE15,Q15,0),IF(R15*if(Z15=true,0.453592,1)=$AE15,S15,0),IF(T15*if(Z15=true,0.453592,1)=$AE15,U15,0),IF(V15*if(Z15=true,0.453592,1)=$AE15,W15,0),IF(X15*if(Z15=true,0.453592,1)=$AE15,Y15,0)) -> 0
B16: 체지방 | D16: {=iferror(vlookup(xlookup(B5,'현황'!O:O,'현황'!O:O,,-1,-1),'현황'!O:S,4,false),0)} -> 0 | F16: 지방 | Z16: FALSE | AA16: =(J16*K16+L16*M16+N16*O16+P16*Q16+R16*S16+T16*U16+V16*W16+X16*Y16)*if(Z16=true,0.453592,1) -> 0 | AB16: =SUM(AE16*AF16*0.025,AE16) -> 0 | AC16: =AB16*87% -> 0 | AD16: =AB16*67% -> 0 | AE16: =MAX(J16,L16,N16,P16,R16,T16,V16,X16)*if(Z16=true,0.453592,1) -> 0 | AF16: =MAX(IF(J16*if(Z16=true,0.453592,1)=$AE16,K16,0),IF(L16*if(Z16=true,0.453592,1)=$AE16,M16,0),IF(N16*if(Z16=true,0.453592,1)=$AE16,O16,0),IF(P16*if(Z16=true,0.453592,1)=$AE16,Q16,0),IF(R16*if(Z16=true,0.453592,1)=$AE16,S16,0),IF(T16*if(Z16=true,0.453592,1)=$AE16,U16,0),IF(V16*if(Z16=true,0.453592,1)=$AE16,W16,0),IF(X16*if(Z16=true,0.453592,1)=$AE16,Y16,0)) -> 0
B17: 체지방률 | D17: =iferror(D16/D14,0) -> 0 | E17: 간식 | H17: 한줄평💬 | P17: 피드백💡 | AA17: =SUM(AA8:AA16) -> 790 | AB17: ⓒ 공여사들 All rights reserved.
B19: 날짜 | D19: 유산소🔥 | H19: 수업⚡ | I19: 운동부위✔️ | J19: 웨이트 운동기록🏋️‍♀️ | AA19: 1회 최대반복 추정🤖 (kg)
B20: 46038 | C20: =if(B20="0/0","",choose(weekday(B20),"(일)","(월)","(화)","(수)","(목)","(금)","(토)")) -> (금) | D20: 걸음수 | E20: 러닝머신 | G20: 사이클 | H20: 수업 | I20: 가슴 | J20: 1set | L20: 2set | N20: 3set | P20: 4set | R20: 5set | T20: 6set | V20: 7set | X20: 8set | Z20: lb (파운드) | AA20: 무게 합 | AB20: 1RM 추정값 | AE20: MAX
B21: =iferror(B20-'현황'!$C$4+1,0) -> 0 | D21: 0 | E21: 0 | G21: 0 | H21: 0
B22: 오늘의 진단✅ | E22: 오늘의 식단🍚 | H22: 웨이트💪 | J22: 무게 | K22: 횟수 | L22: 무게 | M22: 횟수 | N22: 무게 | O22: 횟수 | P22: 무게 | Q22: 횟수 | R22: 무게 | S22: 횟수 | T22: 무게 | U22: 횟수 | V22: 무게 | W22: 횟수 | X22: 무게 | Y22: 횟수 | AB22: 1RM | AC22: 5RM | AD22: 12RM | AE22: 무게 | AF22: 횟수
B23: 숙면🌙 | E23: 아 침 | F23: 탄수화물 | H23: 체스트프레스 | J23: 5 | K23: 8 | L23: 5 | M23: 10 | N23: 5 | O23: 12 | P23: 5 | Q23: 12 | R23: 5 | S23: 12 | Z23: FALSE | AA23: =(J23*K23+L23*M23+N23*O23+P23*Q23+R23*S23+T23*U23+V23*W23+X23*Y23)*if(Z23=true,0.453592,1) -> 270 | AB23: =SUM(AE23*AF23*0.025,AE23) -> 6.5 | AC23: =AB23*87% -> 5.655 | AD23: =AB23*67% -> 4.355 | AE23: =MAX(J23,L23,N23,P23,R23,T23,V23,X23)*if(Z23=true,0.453592,1) -> 5 | AF23: =MAX(IF(J23*if(Z23=true,0.453592,1)=$AE23,K23,0),IF(L23*if(Z23=true,0.453592,1)=$AE23,M23,0),IF(N23*if(Z23=true,0.453592,1)=$AE23,O23,0),IF(P23*if(Z23=true,0.453592,1)=$AE23,Q23,0),IF(R23*if(Z23=true,0.453592,1)=$AE23,S23,0),IF(T23*if(Z23=true,0.453592,1)=$AE23,U23,0),IF(V23*if(Z23=true,0.453592,1)=$AE23,W23,0),IF(X23*if(Z23=true,0.453592,1)=$AE23,Y23,0)) -> 12
B24: 컨디션😀 | F24: 단백질 | H24: 펙덱플라이 | J24: 5 | K24: 12 | L24: 5 | M24: 15 | N24: 5 | O24: 15 | P24: 5 | Q24: 12 | Z24: FALSE | AA24: =(J24*K24+L24*M24+N24*O24+P24*Q24+R24*S24+T24*U24+V24*W24+X24*Y24)*if(Z24=true,0.453592,1) -> 270 | AB24: =SUM(AE24*AF24*0.025,AE24) -> 6.875 | AC24: =AB24*87% -> 5.98125 | AD24: =AB24*67% -> 4.60625 | AE24: =MAX(J24,L24,N24,P24,R24,T24,V24,X24)*if(Z24=true,0.453592,1) -> 5 | AF24: =MAX(IF(J24*if(Z24=true,0.453592,1)=$AE24,K24,0),IF(L24*if(Z24=true,0.453592,1)=$AE24,M24,0),IF(N24*if(Z24=true,0.453592,1)=$AE24,O24,0),IF(P24*if(Z24=true,0.453592,1)=$AE24,Q24,0),IF(R24*if(Z24=true,0.453592,1)=$AE24,S24,0),IF(T24*if(Z24=true,0.453592,1)=$AE24,U24,0),IF(V24*if(Z24=true,0.453592,1)=$AE24,W24,0),IF(X24*if(Z24=true,0.453592,1)=$AE24,Y24,0)) -> 15
B25: 활동강도🔥 | F25: 지방 | Z25: FALSE | AA25: =(J25*K25+L25*M25+N25*O25+P25*Q25+R25*S25+T25*U25+V25*W25+X25*Y25)*if(Z25=true,0.453592,1) -> 0 | AB25: =SUM(AE25*AF25*0.025,AE25) -> 0 | AC25: =AB25*87% -> 0 | AD25: =AB25*67% -> 0 | AE25: =MAX(J25,L25,N25,P25,R25,T25,V25,X25)*if(Z25=true,0.453592,1) -> 0 | AF25: =MAX(IF(J25*if(Z25=true,0.453592,1)=$AE25,K25,0),IF(L25*if(Z25=true,0.453592,1)=$AE25,M25,0),IF(N25*if(Z25=true,0.453592,1)=$AE25,O25,0),IF(P25*if(Z25=true,0.453592,1)=$AE25,Q25,0),IF(R25*if(Z25=true,0.453592,1)=$AE25,S25,0),IF(T25*if(Z25=true,0.453592,1)=$AE25,U25,0),IF(V25*if(Z25=true,0.453592,1)=$AE25,W25,0),IF(X25*if(Z25=true,0.453592,1)=$AE25,Y25,0)) -> 0
B26: 식이조절😇 | D26: FALSE | E26: 점 심 | F26: 탄수화물 | Z26: FALSE | AA26: =(J26*K26+L26*M26+N26*O26+P26*Q26+R26*S26+T26*U26+V26*W26+X26*Y26)*if(Z26=true,0.453592,1) -> 0 | AB26: =SUM(AE26*AF26*0.025,AE26) -> 0 | AC26: =AB26*87% -> 0 | AD26: =AB26*67% -> 0 | AE26: =MAX(J26,L26,N26,P26,R26,T26,V26,X26)*if(Z26=true,0.453592,1) -> 0 | AF26: =MAX(IF(J26*if(Z26=true,0.453592,1)=$AE26,K26,0),IF(L26*if(Z26=true,0.453592,1)=$AE26,M26,0),IF(N26*if(Z26=true,0.453592,1)=$AE26,O26,0),IF(P26*if(Z26=true,0.453592,1)=$AE26,Q26,0),IF(R26*if(Z26=true,0.453592,1)=$AE26,S26,0),IF(T26*if(Z26=true,0.453592,1)=$AE26,U26,0),IF(V26*if(Z26=true,0.453592,1)=$AE26,W26,0),IF(X26*if(Z26=true,0.453592,1)=$AE26,Y26,0)) -> 0
B27: 수분🥛 | D27: FALSE | F27: 단백질 | Z27: FALSE | AA27: =(J27*K27+L27*M27+N27*O27+P27*Q27+R27*S27+T27*U27+V27*W27+X27*Y27)*if(Z27=true,0.453592,1) -> 0 | AB27: =SUM(AE27*AF27*0.025,AE27) -> 0 | AC27: =AB27*87% -> 0 | AD27: =AB27*67% -> 0 | AE27: =MAX(J27,L27,N27,P27,R27,T27,V27,X27)*if(Z27=true,0.453592,1) -> 0 | AF27: =MAX(IF(J27*if(Z27=true,0.453592,1)=$AE27,K27,0),IF(L27*if(Z27=true,0.453592,1)=$AE27,M27,0),IF(N27*if(Z27=true,0.453592,1)=$AE27,O27,0),IF(P27*if(Z27=true,0.453592,1)=$AE27,Q27,0),IF(R27*if(Z27=true,0.453592,1)=$AE27,S27,0),IF(T27*if(Z27=true,0.453592,1)=$AE27,U27,0),IF(V27*if(Z27=true,0.453592,1)=$AE27,W27,0),IF(X27*if(Z27=true,0.453592,1)=$AE27,Y27,0)) -> 0
B28: {="📌최근 인바디 결과 : "&text(xlookup(B20,'현황'!O:O,'현황'!O:O,,-1,-1),"m/d(ddd)")} -> #REF! | F28: 지방 | Z28: FALSE | AA28: =(J28*K28+L28*M28+N28*O28+P28*Q28+R28*S28+T28*U28+V28*W28+X28*Y28)*if(Z28=true,0.453592,1) -> 0 | AB28: =SUM(AE28*AF28*0.025,AE28) -> 0 | AC28: =AB28*87% -> 0 | AD28: =AB28*67% -> 0 | AE28: =MAX(J28,L28,N28,P28,R28,T28,V28,X28)*if(Z28=true,0.453592,1) -> 0 | AF28: =MAX(IF(J28*if(Z28=true,0.453592,1)=$AE28,K28,0),IF(L28*if(Z28=true,0.453592,1)=$AE28,M28,0),IF(N28*if(Z28=true,0.453592,1)=$AE28,O28,0),IF(P28*if(Z28=true,0.453592,1)=$AE28,Q28,0),IF(R28*if(Z28=true,0.453592,1)=$AE28,S28,0),IF(T28*if(Z28=true,0.453592,1)=$AE28,U28,0),IF(V28*if(Z28=true,0.453592,1)=$AE28,W28,0),IF(X28*if(Z28=true,0.453592,1)=$AE28,Y28,0)) -> 0
B29: 몸무게🙈 | D29: {=iferror(vlookup(xlookup(B20,'현황'!O:O,'현황'!O:O,,-1,-1),'현황'!O:S,2,false),0)} -> 0 | E29: 저 녁 | F29: 탄수화물 | Z29: FALSE | AA29: =(J29*K29+L29*M29+N29*O29+P29*Q29+R29*S29+T29*U29+V29*W29+X29*Y29)*if(Z29=true,0.453592,1) -> 0 | AB29: =SUM(AE29*AF29*0.025,AE29) -> 0 | AC29: =AB29*87% -> 0 | AD29: =AB29*67% -> 0 | AE29: =MAX(J29,L29,N29,P29,R29,T29,V29,X29)*if(Z29=true,0.453592,1) -> 0 | AF29: =MAX(IF(J29*if(Z29=true,0.453592,1)=$AE29,K29,0),IF(L29*if(Z29=true,0.453592,1)=$AE29,M29,0),IF(N29*if(Z29=true,0.453592,1)=$AE29,O29,0),IF(P29*if(Z29=true,0.453592,1)=$AE29,Q29,0),IF(R29*if(Z29=true,0.453592,1)=$AE29,S29,0),IF(T29*if(Z29=true,0.453592,1)=$AE29,U29,0),IF(V29*if(Z29=true,0.453592,1)=$AE29,W29,0),IF(X29*if(Z29=true,0.453592,1)=$AE29,Y29,0)) -> 0
B30: 골격근 | D30: {=iferror(vlookup(xlookup(B20,'현황'!O:O,'현황'!O:O,,-1,-1),'현황'!O:S,3,false),0)} -> 0 | F30: 단백질 | Z30: FALSE | AA30: =(J30*K30+L30*M30+N30*O30+P30*Q30+R30*S30+T30*U30+V30*W30+X30*Y30)*if(Z30=true,0.453592,1) -> 0 | AB30: =SUM(AE30*AF30*0.025,AE30) -> 0 | AC30: =AB30*87% -> 0 | AD30: =AB30*67% -> 0 | AE30: =MAX(J30,L30,N30,P30,R30,T30,V30,X30)*if(Z30=true,0.453592,1) -> 0 | AF30: =MAX(IF(J30*if(Z30=true,0.453592,1)=$AE30,K30,0),IF(L30*if(Z30=true,0.453592,1)=$AE30,M30,0),IF(N30*if(Z30=true,0.453592,1)=$AE30,O30,0),IF(P30*if(Z30=true,0.453592,1)=$AE30,Q30,0),IF(R30*if(Z30=true,0.453592,1)=$AE30,S30,0),IF(T30*if(Z30=true,0.453592,1)=$AE30,U30,0),IF(V30*if(Z30=true,0.453592,1)=$AE30,W30,0),IF(X30*if(Z30=true,0.453592,1)=$AE30,Y30,0)) -> 0
B31: 체지방 | D31: {=iferror(vlookup(xlookup(B20,'현황'!O:O,'현황'!O:O,,-1,-1),'현황'!O:S,4,false),0)} -> 0 | F31: 지방 | Z31: FALSE | AA31: =(J31*K31+L31*M31+N31*O31+P31*Q31+R31*S31+T31*U31+V31*W31+X31*Y31)*if(Z31=true,0.453592,1) -> 0 | AB31: =SUM(AE31*AF31*0.025,AE31) -> 0 | AC31: =AB31*87% -> 0 | AD31: =AB31*67% -> 0 | AE31: =MAX(J31,L31,N31,P31,R31,T31,V31,X31)*if(Z31=true,0.453592,1) -> 0 | AF31: =MAX(IF(J31*if(Z31=true,0.453592,1)=$AE31,K31,0),IF(L31*if(Z31=true,0.453592,1)=$AE31,M31,0),IF(N31*if(Z31=true,0.453592,1)=$AE31,O31,0),IF(P31*if(Z31=true,0.453592,1)=$AE31,Q31,0),IF(R31*if(Z31=true,0.453592,1)=$AE31,S31,0),IF(T31*if(Z31=true,0.453592,1)=$AE31,U31,0),IF(V31*if(Z31=true,0.453592,1)=$AE31,W31,0),IF(X31*if(Z31=true,0.453592,1)=$AE31,Y31,0)) -> 0
B32: 체지방률 | D32: =iferror(D31/D29,0) -> 0 | E32: 간식 | H32: 한줄평💬 | P32: 피드백💡 | AA32: =SUM(AA23:AA31) -> 540 | AB32: ⓒ 공여사들 All rights reserved.
B34: 날짜 | D34: 유산소🔥 | H34: 수업⚡ | I34: 운동부위✔️ | J34: 웨이트 운동기록🏋️‍♀️ | AA34: 1회 최대반복 추정🤖 (kg)
B35: 46042 | C35: =if(B35="0/0","",choose(weekday(B35),"(일)","(월)","(화)","(수)","(목)","(금)","(토)")) -> (화) | D35: 걸음수 | E35: 러닝머신 | G35: 사이클 | H35: 수업 | I35: 하체 | J35: 1set | L35: 2set | N35: 3set | P35: 4set | R35: 5set | T35: 6set | V35: 7set | X35: 8set | Z35: lb (파운드) | AA35: 무게 합 | AB35: 1RM 추정값 | AE35: MAX
B36: =iferror(B35-'현황'!$C$4+1,0) -> 0 | D36: 0 | E36: 0 | G36: 0 | H36: 0
B37: 오늘의 진단✅ | E37: 오늘의 식단🍚 | H37: 웨이트💪 | J37: 무게 | K37: 횟수 | L37: 무게 | M37: 횟수 | N37: 무게 | O37: 횟수 | P37: 무게 | Q37: 횟수 | R37: 무게 | S37: 횟수 | T37: 무게 | U37: 횟수 | V37: 무게 | W37: 횟수 | X37: 무게 | Y37: 횟수 | AB37: 1RM | AC37: 5RM | AD37: 12RM | AE37: 무게 | AF37: 횟수
B38: 숙면🌙 | E38: 아 침 | F38: 탄수화물 | H38: 익스텐션 | J38: 12 | K38: 15 | L38: 12 | M38: 15 | N38: 12 | O38: 15 | P38: 12 | Q38: 15 | Z38: FALSE | AA38: =(J38*K38+L38*M38+N38*O38+P38*Q38+R38*S38+T38*U38+V38*W38+X38*Y38)*if(Z38=true,0.453592,1) -> 720 | AB38: =SUM(AE38*AF38*0.025,AE38) -> 16.5 | AC38: =AB38*87% -> 14.355 | AD38: =AB38*67% -> 11.055 | AE38: =MAX(J38,L38,N38,P38,R38,T38,V38,X38)*if(Z38=true,0.453592,1) -> 12 | AF38: =MAX(IF(J38*if(Z38=true,0.453592,1)=$AE38,K38,0),IF(L38*if(Z38=true,0.453592,1)=$AE38,M38,0),IF(N38*if(Z38=true,0.453592,1)=$AE38,O38,0),IF(P38*if(Z38=true,0.453592,1)=$AE38,Q38,0),IF(R38*if(Z38=true,0.453592,1)=$AE38,S38,0),IF(T38*if(Z38=true,0.453592,1)=$AE38,U38,0),IF(V38*if(Z38=true,0.453592,1)=$AE38,W38,0),IF(X38*if(Z38=true,0.453592,1)=$AE38,Y38,0)) -> 15
B39: 컨디션😀 | F39: 단백질 | H39: 컬 | J39: 10 | K39: 15 | L39: 10 | M39: 15 | N39: 10 | O39: 15 | P39: 13 | Q39: 15 | Z39: FALSE | AA39: =(J39*K39+L39*M39+N39*O39+P39*Q39+R39*S39+T39*U39+V39*W39+X39*Y39)*if(Z39=true,0.453592,1) -> 645 | AB39: =SUM(AE39*AF39*0.025,AE39) -> 17.875 | AC39: =AB39*87% -> 15.55125 | AD39: =AB39*67% -> 11.97625 | AE39: =MAX(J39,L39,N39,P39,R39,T39,V39,X39)*if(Z39=true,0.453592,1) -> 13 | AF39: =MAX(IF(J39*if(Z39=true,0.453592,1)=$AE39,K39,0),IF(L39*if(Z39=true,0.453592,1)=$AE39,M39,0),IF(N39*if(Z39=true,0.453592,1)=$AE39,O39,0),IF(P39*if(Z39=true,0.453592,1)=$AE39,Q39,0),IF(R39*if(Z39=true,0.453592,1)=$AE39,S39,0),IF(T39*if(Z39=true,0.453592,1)=$AE39,U39,0),IF(V39*if(Z39=true,0.453592,1)=$AE39,W39,0),IF(X39*if(Z39=true,0.453592,1)=$AE39,Y39,0)) -> 15
B40: 활동강도🔥 | F40: 지방 | H40: 어브덕션 | J40: 33 | K40: 15 | L40: 33 | M40: 15 | N40: 26 | O40: 15 | P40: 33 | Q40: 15 | Z40: FALSE | AA40: =(J40*K40+L40*M40+N40*O40+P40*Q40+R40*S40+T40*U40+V40*W40+X40*Y40)*if(Z40=true,0.453592,1) -> 1875 | AB40: =SUM(AE40*AF40*0.025,AE40) -> 45.375 | AC40: =AB40*87% -> 39.47625 | AD40: =AB40*67% -> 30.40125 | AE40: =MAX(J40,L40,N40,P40,R40,T40,V40,X40)*if(Z40=true,0.453592,1) -> 33 | AF40: =MAX(IF(J40*if(Z40=true,0.453592,1)=$AE40,K40,0),IF(L40*if(Z40=true,0.453592,1)=$AE40,M40,0),IF(N40*if(Z40=true,0.453592,1)=$AE40,O40,0),IF(P40*if(Z40=true,0.453592,1)=$AE40,Q40,0),IF(R40*if(Z40=true,0.453592,1)=$AE40,S40,0),IF(T40*if(Z40=true,0.453592,1)=$AE40,U40,0),IF(V40*if(Z40=true,0.453592,1)=$AE40,W40,0),IF(X40*if(Z40=true,0.453592,1)=$AE40,Y40,0)) -> 15
B41: 식이조절😇 | D41: FALSE | E41: 점 심 | F41: 탄수화물 | Z41: FALSE | AA41: =(J41*K41+L41*M41+N41*O41+P41*Q41+R41*S41+T41*U41+V41*W41+X41*Y41)*if(Z41=true,0.453592,1) -> 0 | AB41: =SUM(AE41*AF41*0.025,AE41) -> 0 | AC41: =AB41*87% -> 0 | AD41: =AB41*67% -> 0 | AE41: =MAX(J41,L41,N41,P41,R41,T41,V41,X41)*if(Z41=true,0.453592,1) -> 0 | AF41: =MAX(IF(J41*if(Z41=true,0.453592,1)=$AE41,K41,0),IF(L41*if(Z41=true,0.453592,1)=$AE41,M41,0),IF(N41*if(Z41=true,0.453592,1)=$AE41,O41,0),IF(P41*if(Z41=true,0.453592,1)=$AE41,Q41,0),IF(R41*if(Z41=true,0.453592,1)=$AE41,S41,0),IF(T41*if(Z41=true,0.453592,1)=$AE41,U41,0),IF(V41*if(Z41=true,0.453592,1)=$AE41,W41,0),IF(X41*if(Z41=true,0.453592,1)=$AE41,Y41,0)) -> 0
B42: 수분🥛 | D42: FALSE | F42: 단백질 | Z42: FALSE | AA42: =(J42*K42+L42*M42+N42*O42+P42*Q42+R42*S42+T42*U42+V42*W42+X42*Y42)*if(Z42=true,0.453592,1) -> 0 | AB42: =SUM(AE42*AF42*0.025,AE42) -> 0 | AC42: =AB42*87% -> 0 | AD42: =AB42*67% -> 0 | AE42: =MAX(J42,L42,N42,P42,R42,T42,V42,X42)*if(Z42=true,0.453592,1) -> 0 | AF42: =MAX(IF(J42*if(Z42=true,0.453592,1)=$AE42,K42,0),IF(L42*if(Z42=true,0.453592,1)=$AE42,M42,0),IF(N42*if(Z42=true,0.453592,1)=$AE42,O42,0),IF(P42*if(Z42=true,0.453592,1)=$AE42,Q42,0),IF(R42*if(Z42=true,0.453592,1)=$AE42,S42,0),IF(T42*if(Z42=true,0.453592,1)=$AE42,U42,0),IF(V42*if(Z42=true,0.453592,1)=$AE42,W42,0),IF(X42*if(Z42=true,0.453592,1)=$AE42,Y42,0)) -> 0
B43: {="📌최근 인바디 결과 : "&text(xlookup(B35,'현황'!O:O,'현황'!O:O,,-1,-1),"m/d(ddd)")} -> #REF! | F43: 지방 | Z43: FALSE | AA43: =(J43*K43+L43*M43+N43*O43+P43*Q43+R43*S43+T43*U43+V43*W43+X43*Y43)*if(Z43=true,0.453592,1) -> 0 | AB43: =SUM(AE43*AF43*0.025,AE43) -> 0 | AC43: =AB43*87% -> 0 | AD43: =AB43*67% -> 0 | AE43: =MAX(J43,L43,N43,P43,R43,T43,V43,X43)*if(Z43=true,0.453592,1) -> 0 | AF43: =MAX(IF(J43*if(Z43=true,0.453592,1)=$AE43,K43,0),IF(L43*if(Z43=true,0.453592,1)=$AE43,M43,0),IF(N43*if(Z43=true,0.453592,1)=$AE43,O43,0),IF(P43*if(Z43=true,0.453592,1)=$AE43,Q43,0),IF(R43*if(Z43=true,0.453592,1)=$AE43,S43,0),IF(T43*if(Z43=true,0.453592,1)=$AE43,U43,0),IF(V43*if(Z43=true,0.453592,1)=$AE43,W43,0),IF(X43*if(Z43=true,0.453592,1)=$AE43,Y43,0)) -> 0
B44: 몸무게🙈 | D44: {=iferror(vlookup(xlookup(B35,'현황'!O:O,'현황'!O:O,,-1,-1),'현황'!O:S,2,false),0)} -> 0 | E44: 저 녁 | F44: 탄수화물 | Z44: FALSE | AA44: =(J44*K44+L44*M44+N44*O44+P44*Q44+R44*S44+T44*U44+V44*W44+X44*Y44)*if(Z44=true,0.453592,1) -> 0 | AB44: =SUM(AE44*AF44*0.025,AE44) -> 0 | AC44: =AB44*87% -> 0 | AD44: =AB44*67% -> 0 | AE44: =MAX(J44,L44,N44,P44,R44,T44,V44,X44)*if(Z44=true,0.453592,1) -> 0 | AF44: =MAX(IF(J44*if(Z44=true,0.453592,1)=$AE44,K44,0),IF(L44*if(Z44=true,0.453592,1)=$AE44,M44,0),IF(N44*if(Z44=true,0.453592,1)=$AE44,O44,0),IF(P44*if(Z44=true,0.453592,1)=$AE44,Q44,0),IF(R44*if(Z44=true,0.453592,1)=$AE44,S44,0),IF(T44*if(Z44=true,0.453592,1)=$AE44,U44,0),IF(V44*if(Z44=true,0.453592,1)=$AE44,W44,0),IF(X44*if(Z44=true,0.453592,1)=$AE44,Y44,0)) -> 0
...
